2022-08-03 10:14:45 INFO === Launch called with kwargs {'uri': 'https://github.com/gtarpenning/wandb-launch-test', 'job': None, 'entry_point': None, 'git_version': None, 'args_list': (), 'name': None, 'resource': None, 'entity': None, 'project': None, 'docker_image': None, 'config': None, 'queue': 'default', 'run_async': False, 'resource_args': None, 'cuda': None} CLI Version: 0.13.0rc6.dev1===
2022-08-03 10:14:50 ERROR Retry attempt failed:
Traceback (most recent call last):
  File "/opt/homebrew/lib/python3.9/site-packages/urllib3/connectionpool.py", line 703, in urlopen
    httplib_response = self._make_request(
  File "/opt/homebrew/lib/python3.9/site-packages/urllib3/connectionpool.py", line 386, in _make_request
    self._validate_conn(conn)
  File "/opt/homebrew/lib/python3.9/site-packages/urllib3/connectionpool.py", line 1042, in _validate_conn
    conn.connect()
  File "/opt/homebrew/lib/python3.9/site-packages/urllib3/connection.py", line 414, in connect
    self.sock = ssl_wrap_socket(
  File "/opt/homebrew/lib/python3.9/site-packages/urllib3/util/ssl_.py", line 449, in ssl_wrap_socket
    ssl_sock = _ssl_wrap_socket_impl(
  File "/opt/homebrew/lib/python3.9/site-packages/urllib3/util/ssl_.py", line 493, in _ssl_wrap_socket_impl
    return ssl_context.wrap_socket(sock, server_hostname=server_hostname)
  File "/opt/homebrew/Cellar/python@3.9/3.9.13_1/Frameworks/Python.framework/Versions/3.9/lib/python3.9/ssl.py", line 501, in wrap_socket
    return self.sslsocket_class._create(
  File "/opt/homebrew/Cellar/python@3.9/3.9.13_1/Frameworks/Python.framework/Versions/3.9/lib/python3.9/ssl.py", line 1041, in _create
    self.do_handshake()
  File "/opt/homebrew/Cellar/python@3.9/3.9.13_1/Frameworks/Python.framework/Versions/3.9/lib/python3.9/ssl.py", line 1310, in do_handshake
    self._sslobj.do_handshake()
ssl.SSLCertVerificationError: [SSL: CERTIFICATE_VERIFY_FAILED] certificate verify failed: unable to get local issuer certificate (_ssl.c:1129)

During handling of the above exception, another exception occurred:

Traceback (most recent call last):
  File "/opt/homebrew/lib/python3.9/site-packages/requests/adapters.py", line 489, in send
    resp = conn.urlopen(
  File "/opt/homebrew/lib/python3.9/site-packages/urllib3/connectionpool.py", line 787, in urlopen
    retries = retries.increment(
  File "/opt/homebrew/lib/python3.9/site-packages/urllib3/util/retry.py", line 592, in increment
    raise MaxRetryError(_pool, url, error or ResponseError(cause))
urllib3.exceptions.MaxRetryError: HTTPSConnectionPool(host='api.wandb.test', port=443): Max retries exceeded with url: /graphql (Caused by SSLError(SSLCertVerificationError(1, '[SSL: CERTIFICATE_VERIFY_FAILED] certificate verify failed: unable to get local issuer certificate (_ssl.c:1129)')))

During handling of the above exception, another exception occurred:

Traceback (most recent call last):
  File "/opt/homebrew/lib/python3.9/site-packages/wandb/sdk/lib/retry.py", line 108, in __call__
    result = self._call_fn(*args, **kwargs)
  File "/opt/homebrew/lib/python3.9/site-packages/wandb/sdk/internal/internal_api.py", line 204, in execute
    return self.client.execute(*args, **kwargs)  # type: ignore
  File "/opt/homebrew/lib/python3.9/site-packages/wandb/vendor/gql-0.2.0/wandb_gql/client.py", line 52, in execute
    result = self._get_result(document, *args, **kwargs)
  File "/opt/homebrew/lib/python3.9/site-packages/wandb/vendor/gql-0.2.0/wandb_gql/client.py", line 60, in _get_result
    return self.transport.execute(document, *args, **kwargs)
  File "/opt/homebrew/lib/python3.9/site-packages/wandb/vendor/gql-0.2.0/wandb_gql/transport/requests.py", line 38, in execute
    request = requests.post(self.url, **post_args)
  File "/opt/homebrew/lib/python3.9/site-packages/requests/api.py", line 115, in post
    return request("post", url, data=data, json=json, **kwargs)
  File "/opt/homebrew/lib/python3.9/site-packages/requests/api.py", line 59, in request
    return session.request(method=method, url=url, **kwargs)
  File "/opt/homebrew/lib/python3.9/site-packages/requests/sessions.py", line 587, in request
    resp = self.send(prep, **send_kwargs)
  File "/opt/homebrew/lib/python3.9/site-packages/requests/sessions.py", line 701, in send
    r = adapter.send(request, **kwargs)
  File "/opt/homebrew/lib/python3.9/site-packages/requests/adapters.py", line 563, in send
    raise SSLError(e, request=request)
requests.exceptions.SSLError: HTTPSConnectionPool(host='api.wandb.test', port=443): Max retries exceeded with url: /graphql (Caused by SSLError(SSLCertVerificationError(1, '[SSL: CERTIFICATE_VERIFY_FAILED] certificate verify failed: unable to get local issuer certificate (_ssl.c:1129)')))
2022-08-03 10:14:58 INFO === Launch called with kwargs {'uri': 'https://github.com/gtarpenning/wandb-launch-test', 'job': None, 'entry_point': None, 'git_version': None, 'args_list': (), 'name': None, 'resource': None, 'entity': None, 'project': None, 'docker_image': None, 'config': None, 'queue': None, 'run_async': False, 'resource_args': None, 'cuda': None} CLI Version: 0.13.0rc6.dev1===
2022-08-03 10:15:02 ERROR Retry attempt failed:
Traceback (most recent call last):
  File "/opt/homebrew/lib/python3.9/site-packages/urllib3/connectionpool.py", line 703, in urlopen
    httplib_response = self._make_request(
  File "/opt/homebrew/lib/python3.9/site-packages/urllib3/connectionpool.py", line 386, in _make_request
    self._validate_conn(conn)
  File "/opt/homebrew/lib/python3.9/site-packages/urllib3/connectionpool.py", line 1042, in _validate_conn
    conn.connect()
  File "/opt/homebrew/lib/python3.9/site-packages/urllib3/connection.py", line 414, in connect
    self.sock = ssl_wrap_socket(
  File "/opt/homebrew/lib/python3.9/site-packages/urllib3/util/ssl_.py", line 449, in ssl_wrap_socket
    ssl_sock = _ssl_wrap_socket_impl(
  File "/opt/homebrew/lib/python3.9/site-packages/urllib3/util/ssl_.py", line 493, in _ssl_wrap_socket_impl
    return ssl_context.wrap_socket(sock, server_hostname=server_hostname)
  File "/opt/homebrew/Cellar/python@3.9/3.9.13_1/Frameworks/Python.framework/Versions/3.9/lib/python3.9/ssl.py", line 501, in wrap_socket
    return self.sslsocket_class._create(
  File "/opt/homebrew/Cellar/python@3.9/3.9.13_1/Frameworks/Python.framework/Versions/3.9/lib/python3.9/ssl.py", line 1041, in _create
    self.do_handshake()
  File "/opt/homebrew/Cellar/python@3.9/3.9.13_1/Frameworks/Python.framework/Versions/3.9/lib/python3.9/ssl.py", line 1310, in do_handshake
    self._sslobj.do_handshake()
ssl.SSLCertVerificationError: [SSL: CERTIFICATE_VERIFY_FAILED] certificate verify failed: unable to get local issuer certificate (_ssl.c:1129)

During handling of the above exception, another exception occurred:

Traceback (most recent call last):
  File "/opt/homebrew/lib/python3.9/site-packages/requests/adapters.py", line 489, in send
    resp = conn.urlopen(
  File "/opt/homebrew/lib/python3.9/site-packages/urllib3/connectionpool.py", line 787, in urlopen
    retries = retries.increment(
  File "/opt/homebrew/lib/python3.9/site-packages/urllib3/util/retry.py", line 592, in increment
    raise MaxRetryError(_pool, url, error or ResponseError(cause))
urllib3.exceptions.MaxRetryError: HTTPSConnectionPool(host='api.wandb.test', port=443): Max retries exceeded with url: /graphql (Caused by SSLError(SSLCertVerificationError(1, '[SSL: CERTIFICATE_VERIFY_FAILED] certificate verify failed: unable to get local issuer certificate (_ssl.c:1129)')))

During handling of the above exception, another exception occurred:

Traceback (most recent call last):
  File "/opt/homebrew/lib/python3.9/site-packages/wandb/sdk/lib/retry.py", line 108, in __call__
    result = self._call_fn(*args, **kwargs)
  File "/opt/homebrew/lib/python3.9/site-packages/wandb/sdk/internal/internal_api.py", line 204, in execute
    return self.client.execute(*args, **kwargs)  # type: ignore
  File "/opt/homebrew/lib/python3.9/site-packages/wandb/vendor/gql-0.2.0/wandb_gql/client.py", line 52, in execute
    result = self._get_result(document, *args, **kwargs)
  File "/opt/homebrew/lib/python3.9/site-packages/wandb/vendor/gql-0.2.0/wandb_gql/client.py", line 60, in _get_result
    return self.transport.execute(document, *args, **kwargs)
  File "/opt/homebrew/lib/python3.9/site-packages/wandb/vendor/gql-0.2.0/wandb_gql/transport/requests.py", line 38, in execute
    request = requests.post(self.url, **post_args)
  File "/opt/homebrew/lib/python3.9/site-packages/requests/api.py", line 115, in post
    return request("post", url, data=data, json=json, **kwargs)
  File "/opt/homebrew/lib/python3.9/site-packages/requests/api.py", line 59, in request
    return session.request(method=method, url=url, **kwargs)
  File "/opt/homebrew/lib/python3.9/site-packages/requests/sessions.py", line 587, in request
    resp = self.send(prep, **send_kwargs)
  File "/opt/homebrew/lib/python3.9/site-packages/requests/sessions.py", line 701, in send
    r = adapter.send(request, **kwargs)
  File "/opt/homebrew/lib/python3.9/site-packages/requests/adapters.py", line 563, in send
    raise SSLError(e, request=request)
requests.exceptions.SSLError: HTTPSConnectionPool(host='api.wandb.test', port=443): Max retries exceeded with url: /graphql (Caused by SSLError(SSLCertVerificationError(1, '[SSL: CERTIFICATE_VERIFY_FAILED] certificate verify failed: unable to get local issuer certificate (_ssl.c:1129)')))
2022-08-03 10:15:26 INFO === Launch called with kwargs {'uri': 'https://github.com/gtarpenning/wandb-launch-test', 'job': None, 'entry_point': None, 'git_version': None, 'args_list': (), 'name': None, 'resource': 'local-process', 'entity': None, 'project': None, 'docker_image': None, 'config': None, 'queue': None, 'run_async': False, 'resource_args': None, 'cuda': None} CLI Version: 0.13.0rc6.dev1===
2022-08-03 10:15:29 ERROR Retry attempt failed:
Traceback (most recent call last):
  File "/opt/homebrew/lib/python3.9/site-packages/urllib3/connectionpool.py", line 703, in urlopen
    httplib_response = self._make_request(
  File "/opt/homebrew/lib/python3.9/site-packages/urllib3/connectionpool.py", line 386, in _make_request
    self._validate_conn(conn)
  File "/opt/homebrew/lib/python3.9/site-packages/urllib3/connectionpool.py", line 1042, in _validate_conn
    conn.connect()
  File "/opt/homebrew/lib/python3.9/site-packages/urllib3/connection.py", line 414, in connect
    self.sock = ssl_wrap_socket(
  File "/opt/homebrew/lib/python3.9/site-packages/urllib3/util/ssl_.py", line 449, in ssl_wrap_socket
    ssl_sock = _ssl_wrap_socket_impl(
  File "/opt/homebrew/lib/python3.9/site-packages/urllib3/util/ssl_.py", line 493, in _ssl_wrap_socket_impl
    return ssl_context.wrap_socket(sock, server_hostname=server_hostname)
  File "/opt/homebrew/Cellar/python@3.9/3.9.13_1/Frameworks/Python.framework/Versions/3.9/lib/python3.9/ssl.py", line 501, in wrap_socket
    return self.sslsocket_class._create(
  File "/opt/homebrew/Cellar/python@3.9/3.9.13_1/Frameworks/Python.framework/Versions/3.9/lib/python3.9/ssl.py", line 1041, in _create
    self.do_handshake()
  File "/opt/homebrew/Cellar/python@3.9/3.9.13_1/Frameworks/Python.framework/Versions/3.9/lib/python3.9/ssl.py", line 1310, in do_handshake
    self._sslobj.do_handshake()
ssl.SSLCertVerificationError: [SSL: CERTIFICATE_VERIFY_FAILED] certificate verify failed: unable to get local issuer certificate (_ssl.c:1129)

During handling of the above exception, another exception occurred:

Traceback (most recent call last):
  File "/opt/homebrew/lib/python3.9/site-packages/requests/adapters.py", line 489, in send
    resp = conn.urlopen(
  File "/opt/homebrew/lib/python3.9/site-packages/urllib3/connectionpool.py", line 787, in urlopen
    retries = retries.increment(
  File "/opt/homebrew/lib/python3.9/site-packages/urllib3/util/retry.py", line 592, in increment
    raise MaxRetryError(_pool, url, error or ResponseError(cause))
urllib3.exceptions.MaxRetryError: HTTPSConnectionPool(host='api.wandb.test', port=443): Max retries exceeded with url: /graphql (Caused by SSLError(SSLCertVerificationError(1, '[SSL: CERTIFICATE_VERIFY_FAILED] certificate verify failed: unable to get local issuer certificate (_ssl.c:1129)')))

During handling of the above exception, another exception occurred:

Traceback (most recent call last):
  File "/opt/homebrew/lib/python3.9/site-packages/wandb/sdk/lib/retry.py", line 108, in __call__
    result = self._call_fn(*args, **kwargs)
  File "/opt/homebrew/lib/python3.9/site-packages/wandb/sdk/internal/internal_api.py", line 204, in execute
    return self.client.execute(*args, **kwargs)  # type: ignore
  File "/opt/homebrew/lib/python3.9/site-packages/wandb/vendor/gql-0.2.0/wandb_gql/client.py", line 52, in execute
    result = self._get_result(document, *args, **kwargs)
  File "/opt/homebrew/lib/python3.9/site-packages/wandb/vendor/gql-0.2.0/wandb_gql/client.py", line 60, in _get_result
    return self.transport.execute(document, *args, **kwargs)
  File "/opt/homebrew/lib/python3.9/site-packages/wandb/vendor/gql-0.2.0/wandb_gql/transport/requests.py", line 38, in execute
    request = requests.post(self.url, **post_args)
  File "/opt/homebrew/lib/python3.9/site-packages/requests/api.py", line 115, in post
    return request("post", url, data=data, json=json, **kwargs)
  File "/opt/homebrew/lib/python3.9/site-packages/requests/api.py", line 59, in request
    return session.request(method=method, url=url, **kwargs)
  File "/opt/homebrew/lib/python3.9/site-packages/requests/sessions.py", line 587, in request
    resp = self.send(prep, **send_kwargs)
  File "/opt/homebrew/lib/python3.9/site-packages/requests/sessions.py", line 701, in send
    r = adapter.send(request, **kwargs)
  File "/opt/homebrew/lib/python3.9/site-packages/requests/adapters.py", line 563, in send
    raise SSLError(e, request=request)
requests.exceptions.SSLError: HTTPSConnectionPool(host='api.wandb.test', port=443): Max retries exceeded with url: /graphql (Caused by SSLError(SSLCertVerificationError(1, '[SSL: CERTIFICATE_VERIFY_FAILED] certificate verify failed: unable to get local issuer certificate (_ssl.c:1129)')))
2022-08-03 10:15:57 INFO === Launch-agent called with kwargs {'ctx': <click.core.Context object at 0x11e906d90>, 'project': None, 'entity': None, 'queues': None, 'max_jobs': None, 'config': None}  CLI Version: 0.13.0rc6.dev1 ===
2022-08-03 10:16:00 ERROR Retry attempt failed:
Traceback (most recent call last):
  File "/opt/homebrew/lib/python3.9/site-packages/urllib3/connectionpool.py", line 703, in urlopen
    httplib_response = self._make_request(
  File "/opt/homebrew/lib/python3.9/site-packages/urllib3/connectionpool.py", line 386, in _make_request
    self._validate_conn(conn)
  File "/opt/homebrew/lib/python3.9/site-packages/urllib3/connectionpool.py", line 1042, in _validate_conn
    conn.connect()
  File "/opt/homebrew/lib/python3.9/site-packages/urllib3/connection.py", line 414, in connect
    self.sock = ssl_wrap_socket(
  File "/opt/homebrew/lib/python3.9/site-packages/urllib3/util/ssl_.py", line 449, in ssl_wrap_socket
    ssl_sock = _ssl_wrap_socket_impl(
  File "/opt/homebrew/lib/python3.9/site-packages/urllib3/util/ssl_.py", line 493, in _ssl_wrap_socket_impl
    return ssl_context.wrap_socket(sock, server_hostname=server_hostname)
  File "/opt/homebrew/Cellar/python@3.9/3.9.13_1/Frameworks/Python.framework/Versions/3.9/lib/python3.9/ssl.py", line 501, in wrap_socket
    return self.sslsocket_class._create(
  File "/opt/homebrew/Cellar/python@3.9/3.9.13_1/Frameworks/Python.framework/Versions/3.9/lib/python3.9/ssl.py", line 1041, in _create
    self.do_handshake()
  File "/opt/homebrew/Cellar/python@3.9/3.9.13_1/Frameworks/Python.framework/Versions/3.9/lib/python3.9/ssl.py", line 1310, in do_handshake
    self._sslobj.do_handshake()
ssl.SSLCertVerificationError: [SSL: CERTIFICATE_VERIFY_FAILED] certificate verify failed: unable to get local issuer certificate (_ssl.c:1129)

During handling of the above exception, another exception occurred:

Traceback (most recent call last):
  File "/opt/homebrew/lib/python3.9/site-packages/requests/adapters.py", line 489, in send
    resp = conn.urlopen(
  File "/opt/homebrew/lib/python3.9/site-packages/urllib3/connectionpool.py", line 787, in urlopen
    retries = retries.increment(
  File "/opt/homebrew/lib/python3.9/site-packages/urllib3/util/retry.py", line 592, in increment
    raise MaxRetryError(_pool, url, error or ResponseError(cause))
urllib3.exceptions.MaxRetryError: HTTPSConnectionPool(host='api.wandb.test', port=443): Max retries exceeded with url: /graphql (Caused by SSLError(SSLCertVerificationError(1, '[SSL: CERTIFICATE_VERIFY_FAILED] certificate verify failed: unable to get local issuer certificate (_ssl.c:1129)')))

During handling of the above exception, another exception occurred:

Traceback (most recent call last):
  File "/opt/homebrew/lib/python3.9/site-packages/wandb/sdk/lib/retry.py", line 108, in __call__
    result = self._call_fn(*args, **kwargs)
  File "/opt/homebrew/lib/python3.9/site-packages/wandb/sdk/internal/internal_api.py", line 204, in execute
    return self.client.execute(*args, **kwargs)  # type: ignore
  File "/opt/homebrew/lib/python3.9/site-packages/wandb/vendor/gql-0.2.0/wandb_gql/client.py", line 52, in execute
    result = self._get_result(document, *args, **kwargs)
  File "/opt/homebrew/lib/python3.9/site-packages/wandb/vendor/gql-0.2.0/wandb_gql/client.py", line 60, in _get_result
    return self.transport.execute(document, *args, **kwargs)
  File "/opt/homebrew/lib/python3.9/site-packages/wandb/vendor/gql-0.2.0/wandb_gql/transport/requests.py", line 38, in execute
    request = requests.post(self.url, **post_args)
  File "/opt/homebrew/lib/python3.9/site-packages/requests/api.py", line 115, in post
    return request("post", url, data=data, json=json, **kwargs)
  File "/opt/homebrew/lib/python3.9/site-packages/requests/api.py", line 59, in request
    return session.request(method=method, url=url, **kwargs)
  File "/opt/homebrew/lib/python3.9/site-packages/requests/sessions.py", line 587, in request
    resp = self.send(prep, **send_kwargs)
  File "/opt/homebrew/lib/python3.9/site-packages/requests/sessions.py", line 701, in send
    r = adapter.send(request, **kwargs)
  File "/opt/homebrew/lib/python3.9/site-packages/requests/adapters.py", line 563, in send
    raise SSLError(e, request=request)
requests.exceptions.SSLError: HTTPSConnectionPool(host='api.wandb.test', port=443): Max retries exceeded with url: /graphql (Caused by SSLError(SSLCertVerificationError(1, '[SSL: CERTIFICATE_VERIFY_FAILED] certificate verify failed: unable to get local issuer certificate (_ssl.c:1129)')))
2022-08-03 10:16:10 INFO === Launch-agent called with kwargs {'ctx': <click.core.Context object at 0x11d046d90>, 'project': None, 'entity': None, 'queues': None, 'max_jobs': None, 'config': None}  CLI Version: 0.13.0rc6.dev1 ===
2022-08-03 10:20:02 INFO === Launch called with kwargs {'uri': 'https://github.com/gtarpenning/wandb-launch-test', 'job': None, 'entry_point': None, 'git_version': None, 'args_list': (), 'name': None, 'resource': None, 'entity': None, 'project': None, 'docker_image': None, 'config': None, 'queue': 'default', 'run_async': False, 'resource_args': None, 'cuda': None} CLI Version: 0.13.0rc6.dev1===
